Workbook

Sheet Frente
A4: Departamento Técnico - Setor Operacional | K4: RDO nº: | M4: Data:
A5: Cliente: | F5: CNPJ: | K5: Contrato/Proposta:
A6: Local do serviço:
A7: Entrada: | C7: < Diurno | E7: < Noturno | G7: Intervalo de almoço: | K7: Nº colaboradores (diurno):
A8: Saída: | C8: < Diurno | E8: < Noturno | G8: Intervalo de Janta: | K8: Nº colaboradores (noturno):
A10: Atividades/Obs.:
A11: Item 01
B12: Serviço: | H12: Início: | L12: =IF(I14="Em andamento", "Pausa:", "Término:") -> Término:
A13: =IF(C12="Flushing/Inibição", "Embarcação: ", "Equipameno: ") -> Equipameno:
A14: Sistema: | H14: Status:
A16: Etapas:
A17: OBS.:
A18: Item 02
B19: Serviço: | H19: Início: | L19: =IF(I21="Em andamento", "Pausa:", "Término:") -> Término:
A20: =IF(C19="Flushing/Inibição", "Embarcação: ", "Equipameno: ") -> Equipameno:
A21: Sistema: | G21: Status:
A23: Etapas:
A24: OBS.:
A25: Item 03
B26: Serviço: | H26: Início: | L26: =IF(I28="Em andamento", "Pausa:", "Término:") -> Término:
A27: =IF(C26="Flushing/Inibição", "Embarcação: ", "Equipameno: ") -> Equipameno:
A28: Sistema: | G28: Status:
A30: Etapas:
A31: OBS.:
A32: Item 04
B33: Serviço: | H33: Início: | L33: =IF(I35="Em andamento", "Pausa:", "Término:") -> Término:
A34: =IF(C33="Flushing/Inibição", "Embarcação: ", "Equipameno: ") -> Equipameno:
A35: Sistema: | G35: Status:
A37: Etapas:
A38: OBS.:
A39: Item 05
B40: Serviço: | H40: Início: | L40: =IF(I42="Em andamento", "Pausa:", "Término:") -> Término:
A41: =IF(C40="Flushing/Inibição", "Embarcação: ", "Equipameno: ") -> Equipameno:
A42: Sistema: | G42: Status:
A44: Etapas:
A45: OBS.:
A46: Item 06
B47: Serviço: | H47: Início: | L47: =IF(I49="Em andamento", "Pausa:", "Término:") -> Término:
A48: =IF(C47="Flushing/Inibição", "Embarcação: ", "Equipameno: ") -> Equipameno:
A49: Sistema: | G49: Status:
...

Sheet Verso
A4: Departamento Técnico - Setor Operacional | F4: =Frente!F4 | K4: RDO nº: | L4: =Frente!L4 | M4: Data: | N4: =Frente!N4
A5: Cliente: | B5: =Frente!B5 | F5: CNPJ: | G5: =Frente!G5 | K5: Contrato/Proposta: | M5: =Frente!M5
A6: Local do serviço: | C6: =Frente!C6
A7: Registros fotográficos
A79: Líder: | B79: =Frente!B79 | G79: Responsável:
A80: Cargo: | B80: =Frente!B80 | G80: Cargo:
A81: Ass.: | G81: Ass.:
N83: Ver 2.0 - 05/24
